Workbook

Sheet 📦产品库
A1: 📦 产品库 | 扭捏niunie 线下店铺
A2: 💡 点击图片列链接可查看商品图片 | 支持按货号/名称/颜色/尺码筛选
A3: 序号 | B3: 货号(SKU) | C3: 款式编码 | D3: 商品名称 | E3: 颜色 | F3: 尺码 | G3: 售价(¥) | H3: 库存 | I3: 图片链接 | J3: 淘宝链接
A4: 1 | B4: NS2614-L | C4: NS2614 | D4: 扭捏niunie 复古格子全羊毛格子外套七分袖短裤宽松衬衫上衣女 | E4: 七分袖格子毛呢外套 | F4: L | G4: 799 | H4: 6 | I4: https://img.alicdn.com/bao/uploaded/i1/2217590670593/O1CN014SZXqr1GFdzaJafbf~crop,0,57,1440,1440~_!!2217590670593.jpg | J4: http://item.taobao.com/item.htm?id=1025388691256
A5: 2 | B5: NS2614-M | C5: NS2614 | D5: 扭捏niunie 复古格子全羊毛格子外套七分袖短裤宽松衬衫上衣女 | E5: 七分袖格子毛呢外套 | F5: M | G5: 799 | H5: 1 | I5: https://img.alicdn.com/bao/uploaded/i1/2217590670593/O1CN014SZXqr1GFdzaJafbf~crop,0,57,1440,1440~_!!2217590670593.jpg | J5: http://item.taobao.com/item.htm?id=1025388691256
A6: 3 | B6: NS2614-S | C6: NS2614 | D6: 扭捏niunie 复古格子全羊毛格子外套七分袖短裤宽松衬衫上衣女 | E6: 七分袖格子毛呢外套 | F6: S | G6: 799 | H6: 0 | I6: https://img.alicdn.com/bao/uploaded/i1/2217590670593/O1CN014SZXqr1GFdzaJafbf~crop,0,57,1440,1440~_!!2217590670593.jpg | J6: http://item.taobao.com/item.htm?id=1025388691256
A7: 4 | B7: NS2613-M | C7: NS2613 | D7: 扭捏niunie 黄色小碎花两面穿半身裙女打褶中长款甜美A字伞裙夏季 | E7: 黄色小碎花两面穿半身裙 | F7: M | G7: 439 | H7: 4 | I7: https://img.alicdn.com/bao/uploaded/i3/2217590670593/O1CN013VOeEz1GFdzbUPeAA~crop,0,240,1440,1440~_!!2217590670593.jpg | J7: http://item.taobao.com/item.htm?id=1026753508485
A8: 5 | B8: NS2613-S | C8: NS2613 | D8: 扭捏niunie 黄色小碎花两面穿半身裙女打褶中长款甜美A字伞裙夏季 | E8: 黄色小碎花两面穿半身裙 | F8: S | G8: 439 | H8: 2 | I8: https://img.alicdn.com/bao/uploaded/i3/2217590670593/O1CN013VOeEz1GFdzbUPeAA~crop,0,240,1440,1440~_!!2217590670593.jpg | J8: http://item.taobao.com/item.htm?id=1026753508485
A9: 6 | B9: NS2611-M | C9: NS2611+NS2612 | D9: 扭捏niunie甜美清新花边口袋樱桃提花拼接圆领短袖衬衫花苞裤套装 | E9: 樱桃提花有口袋衬衫 | F9: M | G9: 369 | H9: 23 | I9: https://img.alicdn.com/bao/uploaded/i2/2217590670593/O1CN01xgSwHZ1GFdzaMGyRv~crop,0,240,1440,1440~_!!2217590670593.jpg | J9: http://item.taobao.com/item.htm?id=1024384959107
A10: 7 | B10: NS2612-M | C10: NS2611+NS2612 | D10: 扭捏niunie甜美清新花边口袋樱桃提花拼接圆领短袖衬衫花苞裤套装 | E10: 樱桃花苞裤 | F10: M | G10: 329 | H10: 2 | I10: https://img.alicdn.com/bao/uploaded/i2/2217590670593/O1CN01CHDMQM1GFdzZvCfJO~crop,0,240,1440,1440~_!!2217590670593.jpg | J10: http://item.taobao.com/item.htm?id=1024384959107
A11: 8 | B11: NS2611-S | C11: NS2611+NS2612 | D11: 扭捏niunie甜美清新花边口袋樱桃提花拼接圆领短袖衬衫花苞裤套装 | E11: 樱桃提花有口袋衬衫 | F11: S | G11: 369 | H11: 11 | I11: https://img.alicdn.com/bao/uploaded/i2/2217590670593/O1CN01xgSwHZ1GFdzaMGyRv~crop,0,240,1440,1440~_!!2217590670593.jpg | J11: http://item.taobao.com/item.htm?id=1024384959107
A12: 9 | B12: NS2612-S | C12: NS2611+NS2612 | D12: 扭捏niunie甜美清新花边口袋樱桃提花拼接圆领短袖衬衫花苞裤套装 | E12: 樱桃花苞裤 | F12: S | G12: 329 | H12: 0 | I12: https://img.alicdn.com/bao/uploaded/i2/2217590670593/O1CN01CHDMQM1GFdzZvCfJO~crop,0,240,1440,1440~_!!2217590670593.jpg | J12: http://item.taobao.com/item.htm?id=1024384959107
A13: 10 | B13: NS2610-M | C13: NS2610 | D13: 扭捏niunie 亚麻复古彩色格子荷叶边短裙抽褶拼接修身半身裙女 | E13: 彩色亚麻格子短裙 | F13: M | G13: 529 | H13: 10 | I13: https://img.alicdn.com/bao/uploaded/i3/2217590670593/O1CN01o0MRbu1GFdza9nw57~crop,0,240,1440,1440~_!!2217590670593.jpg | J13: http://item.taobao.com/item.htm?id=1026750680382
A14: 11 | B14: NS2610-S | C14: NS2610 | D14: 扭捏niunie 亚麻复古彩色格子荷叶边短裙抽褶拼接修身半身裙女 | E14: 彩色亚麻格子短裙 | F14: S | G14: 529 | H14: 10 | I14: https://img.alicdn.com/bao/uploaded/i3/2217590670593/O1CN01o0MRbu1GFdza9nw57~crop,0,240,1440,1440~_!!2217590670593.jpg | J14: http://item.taobao.com/item.htm?id=1026750680382
A15: 12 | B15: NS2609-M | C15: NS2609 | D15: 扭捏niunie 青苹果天使十字绣针织衫长袖圆领T恤甜美宽松上衣女 | E15: 青苹果天使针织长袖t | F15: M | G15: 199 | H15: 22 | I15: https://img.alicdn.com/bao/uploaded/i4/2217590670593/O1CN01oHujxO1GFdzZY3erp~crop,0,240,1440,1440~_!!2217590670593.jpg | J15: http://item.taobao.com/item.htm?id=1024381439350
... A78: 75 | B78: NN2533-L | C78: NN2533 | D78: 【秋天的童话】原创巴恩风剪花小格子重工半身裙复古中长裙女秋款 | E78: 彩色剪花小格子半身裙 | F78: L | G78: 429 | H78: 15 | I78: https://img.alicdn.com/bao/uploaded/i4/2217590670593/O1CN01g52yMQ1GFdx0brzbm_!!2217590670593.jpg | J78: http://item.taobao.com/item.htm?id=965709300675
A79: 76 | C79: NN2530 | D79: 扭捏niunie 小浣熊松鼠趣味提花蓝色长袖衬衫宽松全棉纽扣上衣女 | E79: 定制面料 需要等待 | F79: M | G79: 339 | H79: 4 | I79: https://img.alicdn.com/bao/uploaded/i3/2217590670593/O1CN01RZwv0i1GFdxBBivtA_!!2217590670593.jpg | J79: http://item.taobao.com/item.htm?id=963888151342
A80: 77 | C80: NN2530 | D80: 扭捏niunie 小浣熊松鼠趣味提花蓝色长袖衬衫宽松全棉纽扣上衣女 | E80: 定制面料 需要等待 | F80: S | G80: 339 | H80: 8 | I80: https://img.alicdn.com/bao/uploaded/i3/2217590670593/O1CN01RZwv0i1GFdxBBivtA_!!2217590670593.jpg | J80: http://item.taobao.com/item.htm?id=963888151342
A81: 78 | C81: NN2536 | D81: 扭捏niunie 多巴胺提花蓝色慵懒风休闲长裤宽松显瘦百搭直筒裤女 | E81: 定制面料 需要等待 | F81: M | G81: 319 | H81: 1 | I81: https://img.alicdn.com/bao/uploaded/i3/2217590670593/O1CN01RZwv0i1GFdxBBivtA_!!2217590670593.jpg | J81: http://item.taobao.com/item.htm?id=965734072577
A82: 79 | C82: NN2536 | D82: 扭捏niunie 多巴胺提花蓝色慵懒风休闲长裤宽松显瘦百搭直筒裤女 | E82: 定制面料 需要等待 | F82: S | G82: 319 | H82: 0 | I82: https://img.alicdn.com/bao/uploaded/i3/2217590670593/O1CN01RZwv0i1GFdxBBivtA_!!2217590670593.jpg | J82: http://item.taobao.com/item.htm?id=965734072577
A83: 80 | B83: TNW-0702-褐L | C83: TNW-0702 | D83: 扭捏niunie 乐谱印花复古长袖T恤进口美利奴羊毛天丝修身内搭上衣 | E83: 茶褐色天丝羊毛长袖t | F83: L | G83: 299 | H83: 2 | I83: https://img.alicdn.com/bao/uploaded/i4/2217590670593/O1CN01yjUReo1GFdx1hYVgl_!!2217590670593.jpg | J83: http://item.taobao.com/item.htm?id=965685763792
A84: 81 | B84: TNW-0702-绿L | C84: TNW-0702 | D84: 扭捏niunie 乐谱印花复古长袖T恤进口美利奴羊毛天丝修身内搭上衣 | E84: 草绿色天丝羊毛长袖t | F84: L | G84: 299 | H84: 5 | I84: https://img.alicdn.com/bao/uploaded/i1/2217590670593/O1CN019qHJlo1GFdx12brW4_!!2217590670593.jpg | J84: http://item.taobao.com/item.htm?id=965685763792
A85: 82 | B85: TNW-0702-褐M | C85: TNW-0702 | D85: 扭捏niunie 乐谱印花复古长袖T恤进口美利奴羊毛天丝修身内搭上衣 | E85: 茶褐色天丝羊毛长袖t | F85: M | G85: 299 | H85: 3 | I85: https://img.alicdn.com/bao/uploaded/i4/2217590670593/O1CN01yjUReo1GFdx1hYVgl_!!2217590670593.jpg | J85: http://item.taobao.com/item.htm?id=965685763792
A86: 83 | B86: TNW-0702-绿M | C86: TNW-0702 | D86: 扭捏niunie 乐谱印花复古长袖T恤进口美利奴羊毛天丝修身内搭上衣 | E86: 草绿色天丝羊毛长袖t | F86: M | G86: 299 | H86: 7 | I86: https://img.alicdn.com/bao/uploaded/i1/2217590670593/O1CN019qHJlo1GFdx12brW4_!!2217590670593.jpg | J86: http://item.taobao.com/item.htm?id=965685763792
A87: 84 | B87: TNW-0702-褐S | C87: TNW-0702 | D87: 扭捏niunie 乐谱印花复古长袖T恤进口美利奴羊毛天丝修身内搭上衣 | E87: 茶褐色天丝羊毛长袖t | F87: S | G87: 299 | H87: 3 | I87: https://img.alicdn.com/bao/uploaded/i4/2217590670593/O1CN01yjUReo1GFdx1hYVgl_!!2217590670593.jpg | J87: http://item.taobao.com/item.htm?id=965685763792
A88: 85 | B88: TNW-0702-绿S | C88: TNW-0702 | D88: 扭捏niunie 乐谱印花复古长袖T恤进口美利奴羊毛天丝修身内搭上衣 | E88: 草绿色天丝羊毛长袖t | F88: S | G88: 299 | H88: 10 | I88: https://img.alicdn.com/bao/uploaded/i1/2217590670593/O1CN019qHJlo1GFdx12brW4_!!2217590670593.jpg | J88: http://item.taobao.com/item.htm?id=965685763792
A89: 86 | B89: TNW-0915-M | C89: TNW-0802 | D89: 扭捏niunie法式复古撞色拼接衬衫澳洲进口美利奴羊毛缩绒工艺上衣 | E89: 浅绿色花苞裙 | F89: M | G89: 499 | H89: 3 | I89: https://img.alicdn.com/bao/uploaded/i1/2217590670593/O1CN01wihPxS1GFdwvCQXKy_!!2217590670593.jpg | J89: http://item.taobao.com/item.htm?id=965686756371
A90: 87 | B90: TNW-0915-S | C90: TNW-0802 | D90: 扭捏niunie法式复古撞色拼接衬衫澳洲进口美利奴羊毛缩绒工艺上衣 | E90: 浅绿色花苞裙 | F90: S | G90: 499 | H90: 3 | I90: https://img.alicdn.com/bao/uploaded/i1/2217590670593/O1CN01wihPxS1GFdwvCQXKy_!!2217590670593.jpg | J90: http://item.taobao.com/item.htm?id=965686756371
A91: 88 | B91: TNW-1010-M | C91: TNW-1010 | D91: 扭捏niunie 复古vintage格子碎花拼接半身裙修身显瘦田园风中长裙 | E91: 格子碎花拼接半裙 | F91: M | G91: 439 | H91: 4 | I91: https://img.alicdn.com/bao/uploaded/i4/2217590670593/O1CN01eVMZOI1GFdsWomFSu_!!2217590670593.jpg | J91: http://item.taobao.com/item.htm?id=965910959682
A92: 89 | B92: TNW-1010-S | C92: TNW-1010 | D92: 扭捏niunie 复古vintage格子碎花拼接半身裙修身显瘦田园风中长裙 | E92: 格子碎花拼接半裙 | F92: S | G92: 439 | H92: 6 | I92: https://img.alicdn.com/bao/uploaded/i4/2217590670593/O1CN01eVMZOI1GFdsWomFSu_!!2217590670593.jpg | J92: http://item.taobao.com/item.htm?id=965910959682
A93: 90 | B93: TNW-0918-M | C93: TNW-0918 | D93: 【我只想睡觉】原创印花圆领毛巾卫衣复古宽松上衣 扭捏niunie | E93: 撞色圆领卫衣 | F93: M | G93: 299 | H93: 7 | I93: https://img.alicdn.com/bao/uploaded/i2/2217590670593/O1CN01uKNQeD1GFdwzZUDc8_!!2217590670593.jpg | J93: http://item.taobao.com/item.htm?id=965673059752
A94: 91 | B94: TNW-0918-S | C94: TNW-0918 | D94: 【我只想睡觉】原创印花圆领毛巾卫衣复古宽松上衣 扭捏niunie | E94: 撞色圆领卫衣 | F94: S | G94: 299 | H94: 11 | I94: https://img.alicdn.com/bao/uploaded/i2/2217590670593/O1CN01uKNQeD1GFdwzZUDc8_!!2217590670593.jpg | J94: http://item.taobao.com/item.htm?id=965673059752
... A110: 107 | B110: NN2537-S | C110: NN2537-2538 | D110: 扭捏niunie 复古休闲翻领牛仔外套格子拼接A字半裙全棉高级感套装 | E110: 牛仔外套 | F110: S | G110: 369 | H110: 0 | I110: https://img.alicdn.com/bao/uploaded/i1/2217590670593/O1CN01BnonAW1GFdwvincOo_!!2217590670593.jpg | J110: http://item.taobao.com/item.htm?id=965053737716
A111: 108 | C111: NN-2515 | D111: 扭捏niunie 复古vintage宽松慵懒感上衣 果实扣100%苎麻衬衫夏季 | E111: 黄色 | F111: L | G111: 398 | H111: 11 | I111: https://img.alicdn.com/bao/uploaded/i4/2217590670593/O1CN01Z5hiwq1GFdv2jmgHC_!!2217590670593.jpg | J111: http://item.taobao.com/item.htm?id=915074198906
A112: 109 | C112: NN-2515 | D112: 扭捏niunie 复古vintage宽松慵懒感上衣 果实扣100%苎麻衬衫夏季 | E112: 黄色 | F112: M | G112: 398 | H112: 25 | I112: https://img.alicdn.com/bao/uploaded/i4/2217590670593/O1CN01Z5hiwq1GFdv2jmgHC_!!2217590670593.jpg | J112: http://item.taobao.com/item.htm?id=915074198906
A113: 110 | C113: NN-2515 | D113: 扭捏niunie 复古vintage宽松慵懒感上衣 果实扣100%苎麻衬衫夏季 | E113: 黄色 | F113: S | G113: 398 | H113: 16 | I113: https://img.alicdn.com/bao/uploaded/i4/2217590670593/O1CN01Z5hiwq1GFdv2jmgHC_!!2217590670593.jpg | J113: http://item.taobao.com/item.htm?id=915074198906
A114: 111 | B114: NTF0311W-1-L | C114: NTF-0311 | D114: 扭捏 少女的祈祷 花边拼接蛋糕a字小短裙白色半身裙 防走光内衬 | E114: 白色拼接短裙 （绗缝位置改版） | F114: L | G114: 338 | H114: 13 | I114: https://img.alicdn.com/bao/uploaded/i1/2217590670593/O1CN01ZmqRQD1GFdwea86Gu_!!2217590670593.jpg | J114: http://item.taobao.com/item.htm?id=805155843613
A115: 112 | B115: NTF0311W-1-M | C115: NTF-0311 | D115: 扭捏 少女的祈祷 花边拼接蛋糕a字小短裙白色半身裙 防走光内衬 | E115: 白色拼接短裙 （绗缝位置改版） | F115: M | G115: 338 | H115: 17 | I115: https://img.alicdn.com/bao/uploaded/i1/2217590670593/O1CN01ZmqRQD1GFdwea86Gu_!!2217590670593.jpg | J115: http://item.taobao.com/item.htm?id=805155843613
A116: 113 | B116: NTF0311W-1-S | C116: NTF-0311 | D116: 扭捏 少女的祈祷 花边拼接蛋糕a字小短裙白色半身裙 防走光内衬 | E116: 白色拼接短裙 （绗缝位置改版） | F116: S | G116: 338 | H116: 13 | I116: https://img.alicdn.com/bao/uploaded/i1/2217590670593/O1CN01ZmqRQD1GFdwea86Gu_!!2217590670593.jpg | J116: http://item.taobao.com/item.htm?id=805155843613
A117: 114 | B117: NTF0307B-L | C117: NTF0307 | D117: 扭捏niunie 玫瑰小猫可爱印花 弹力花边圆领正肩白色短袖T恤女夏 | E117: 玫瑰印花白色T恤 | F117: L | G117: 198 | H117: 0 | I117: https://img.alicdn.com/bao/uploaded/i4/2217590670593/O1CN01Luzo9Q1GFdvJKTxCd_!!2217590670593.jpg | J117: http://item.taobao.com/item.htm?id=924779585209
...

Sheet 🧾每日销售
A1: 🧾 每日销售开单 | 输入货号自动带出商品信息
A2: 日期： | B2: 2026-04-07 | C2: 当班人员： | D2: 店员A | F2: 人数： | G2: 1 | H2: POS核对(¥)： | J2: 0 | K2: 系统合计(¥)： | L2: =SUM(K5:K504) | M2: 差异(¥)： | N2: =J2-L2
A3: 💡 在【货号】列输入货号 → 商品信息自动填入 → 填【实收金额】→ 每单记录成交人，方便大单奖励核算
A4: 序号 | B4: 货号(SKU) | C4: 商品名称 | D4: 颜色 | E4: 尺码 | F4: 标价(¥) | G4: 实收(¥) | H4: 数量 | I4: 小计(¥) | J4: 成交人 | K4: 大单奖励(¥) | L4: 备注
A5: =IF(B5="","",ROW()-4) | C5: =IF(B5="","",IFERROR(VLOOKUP(B5,'📦产品库'!$B$4:$D$9999,2,0),"⚠️未找到")) | D5: =IF(B5="","",IFERROR(VLOOKUP(B5,'📦产品库'!$B$4:$E$9999,4,0),"")) | E5: =IF(B5="","",IFERROR(VLOOKUP(B5,'📦产品库'!$B$4:$F$9999,5,0),"")) | F5: =IF(B5="","",IFERROR(VLOOKUP(B5,'📦产品库'!$B$4:$G$9999,6,0),"")) | H5: =IF(B5="","",1) | I5: =IF(B5="","",IF(G5<>"",G5*H5,F5*H5)) | K5: =IF(B5="","",IF(G5>=2000,20,IF(G5>=1000,10,0)))
A6: =IF(B6="","",ROW()-4) | C6: =IF(B6="","",IFERROR(VLOOKUP(B6,'📦产品库'!$B$4:$D$9999,2,0),"⚠️未找到")) | D6: =IF(B6="","",IFERROR(VLOOKUP(B6,'📦产品库'!$B$4:$E$9999,4,0),"")) | E6: =IF(B6="","",IFERROR(VLOOKUP(B6,'📦产品库'!$B$4:$F$9999,5,0),"")) | F6: =IF(B6="","",IFERROR(VLOOKUP(B6,'📦产品库'!$B$4:$G$9999,6,0),"")) | H6: =IF(B6="","",1) | I6: =IF(B6="","",IF(G6<>"",G6*H6,F6*H6)) | K6: =IF(B6="","",IF(G6>=2000,20,IF(G6>=1000,10,0)))
A7: =IF(B7="","",ROW()-4) | C7: =IF(B7="","",IFERROR(VLOOKUP(B7,'📦产品库'!$B$4:$D$9999,2,0),"⚠️未找到")) | D7: =IF(B7="","",IFERROR(VLOOKUP(B7,'📦产品库'!$B$4:$E$9999,4,0),"")) | E7: =IF(B7="","",IFERROR(VLOOKUP(B7,'📦产品库'!$B$4:$F$9999,5,0),"")) | F7: =IF(B7="","",IFERROR(VLOOKUP(B7,'📦产品库'!$B$4:$G$9999,6,0),"")) | H7: =IF(B7="","",1) | I7: =IF(B7="","",IF(G7<>"",G7*H7,F7*H7)) | K7: =IF(B7="","",IF(G7>=2000,20,IF(G7>=1000,10,0)))
A8: =IF(B8="","",ROW()-4) | C8: =IF(B8="","",IFERROR(VLOOKUP(B8,'📦产品库'!$B$4:$D$9999,2,0),"⚠️未找到")) | D8: =IF(B8="","",IFERROR(VLOOKUP(B8,'📦产品库'!$B$4:$E$9999,4,0),"")) | E8: =IF(B8="","",IFERROR(VLOOKUP(B8,'📦产品库'!$B$4:$F$9999,5,0),"")) | F8: =IF(B8="","",IFERROR(VLOOKUP(B8,'📦产品库'!$B$4:$G$9999,6,0),"")) | H8: =IF(B8="","",1) | I8: =IF(B8="","",IF(G8<>"",G8*H8,F8*H8)) | K8: =IF(B8="","",IF(G8>=2000,20,IF(G8>=1000,10,0)))
A9: =IF(B9="","",ROW()-4) | C9: =IF(B9="","",IFERROR(VLOOKUP(B9,'📦产品库'!$B$4:$D$9999,2,0),"⚠️未找到")) | D9: =IF(B9="","",IFERROR(VLOOKUP(B9,'📦产品库'!$B$4:$E$9999,4,0),"")) | E9: =IF(B9="","",IFERROR(VLOOKUP(B9,'📦产品库'!$B$4:$F$9999,5,0),"")) | F9: =IF(B9="","",IFERROR(VLOOKUP(B9,'📦产品库'!$B$4:$G$9999,6,0),"")) | H9: =IF(B9="","",1) | I9: =IF(B9="","",IF(G9<>"",G9*H9,F9*H9)) | K9: =IF(B9="","",IF(G9>=2000,20,IF(G9>=1000,10,0)))
A10: =IF(B10="","",ROW()-4) | C10: =IF(B10="","",IFERROR(VLOOKUP(B10,'📦产品库'!$B$4:$D$9999,2,0),"⚠️未找到")) | D10: =IF(B10="","",IFERROR(VLOOKUP(B10,'📦产品库'!$B$4:$E$9999,4,0),"")) | E10: =IF(B10="","",IFERROR(VLOOKUP(B10,'📦产品库'!$B$4:$F$9999,5,0),"")) | F10: =IF(B10="","",IFERROR(VLOOKUP(B10,'📦产品库'!$B$4:$G$9999,6,0),"")) | H10: =IF(B10="","",1) | I10: =IF(B10="","",IF(G10<>"",G10*H10,F10*H10)) | K10: =IF(B10="","",IF(G10>=2000,20,IF(G10>=1000,10,0)))
A11: =IF(B11="","",ROW()-4) | C11: =IF(B11="","",IFERROR(VLOOKUP(B11,'📦产品库'!$B$4:$D$9999,2,0),"⚠️未找到")) | D11: =IF(B11="","",IFERROR(VLOOKUP(B11,'📦产品库'!$B$4:$E$9999,4,0),"")) | E11: =IF(B11="","",IFERROR(VLOOKUP(B11,'📦产品库'!$B$4:$F$9999,5,0),"")) | F11: =IF(B11="","",IFERROR(VLOOKUP(B11,'📦产品库'!$B$4:$G$9999,6,0),"")) | H11: =IF(B11="","",1) | I11: =IF(B11="","",IF(G11<>"",G11*H11,F11*H11)) | K11: =IF(B11="","",IF(G11>=2000,20,IF(G11>=1000,10,0)))
A12: =IF(B12="","",ROW()-4) | C12: =IF(B12="","",IFERROR(VLOOKUP(B12,'📦产品库'!$B$4:$D$9999,2,0),"⚠️未找到")) | D12: =IF(B12="","",IFERROR(VLOOKUP(B12,'📦产品库'!$B$4:$E$9999,4,0),"")) | E12: =IF(B12="","",IFERROR(VLOOKUP(B12,'📦产品库'!$B$4:$F$9999,5,0),"")) | F12: =IF(B12="","",IFERROR(VLOOKUP(B12,'📦产品库'!$B$4:$G$9999,6,0),"")) | H12: =IF(B12="","",1) | I12: =IF(B12="","",IF(G12<>"",G12*H12,F12*H12)) | K12: =IF(B12="","",IF(G12>=2000,20,IF(G12>=1000,10,0)))
A13: =IF(B13="","",ROW()-4) | C13: =IF(B13="","",IFERROR(VLOOKUP(B13,'📦产品库'!$B$4:$D$9999,2,0),"⚠️未找到")) | D13: =IF(B13="","",IFERROR(VLOOKUP(B13,'📦产品库'!$B$4:$E$9999,4,0),"")) | E13: =IF(B13="","",IFERROR(VLOOKUP(B13,'📦产品库'!$B$4:$F$9999,5,0),"")) | F13: =IF(B13="","",IFERROR(VLOOKUP(B13,'📦产品库'!$B$4:$G$9999,6,0),"")) | H13: =IF(B13="","",1) | I13: =IF(B13="","",IF(G13<>"",G13*H13,F13*H13)) | K13: =IF(B13="","",IF(G13>=2000,20,IF(G13>=1000,10,0)))
A14: =IF(B14="","",ROW()-4) | C14: =IF(B14="","",IFERROR(VLOOKUP(B14,'📦产品库'!$B$4:$D$9999,2,0),"⚠️未找到")) | D14: =IF(B14="","",IFERROR(VLOOKUP(B14,'📦产品库'!$B$4:$E$9999,4,0),"")) | E14: =IF(B14="","",IFERROR(VLOOKUP(B14,'📦产品库'!$B$4:$F$9999,5,0),"")) | F14: =IF(B14="","",IFERROR(VLOOKUP(B14,'📦产品库'!$B$4:$G$9999,6,0),"")) | H14: =IF(B14="","",1) | I14: =IF(B14="","",IF(G14<>"",G14*H14,F14*H14)) | K14: =IF(B14="","",IF(G14>=2000,20,IF(G14>=1000,10,0)))
A15: =IF(B15="","",ROW()-4) | C15: =IF(B15="","",IFERROR(VLOOKUP(B15,'📦产品库'!$B$4:$D$9999,2,0),"⚠️未找到")) | D15: =IF(B15="","",IFERROR(VLOOKUP(B15,'📦产品库'!$B$4:$E$9999,4,0),"")) | E15: =IF(B15="","",IFERROR(VLOOKUP(B15,'📦产品库'!$B$4:$F$9999,5,0),"")) | F15: =IF(B15="","",IFERROR(VLOOKUP(B15,'📦产品库'!$B$4:$G$9999,6,0),"")) | H15: =IF(B15="","",1) | I15: =IF(B15="","",IF(G15<>"",G15*H15,F15*H15)) | K15: =IF(B15="","",IF(G15>=2000,20,IF(G15>=1000,10,0)))
A16: =IF(B16="","",ROW()-4) | C16: =IF(B16="","",IFERROR(VLOOKUP(B16,'📦产品库'!$B$4:$D$9999,2,0),"⚠️未找到")) | D16: =IF(B16="","",IFERROR(VLOOKUP(B16,'📦产品库'!$B$4:$E$9999,4,0),"")) | E16: =IF(B16="","",IFERROR(VLOOKUP(B16,'📦产品库'!$B$4:$F$9999,5,0),"")) | F16: =IF(B16="","",IFERROR(VLOOKUP(B16,'📦产品库'!$B$4:$G$9999,6,0),"")) | H16: =IF(B16="","",1) | I16: =IF(B16="","",IF(G16<>"",G16*H16,F16*H16)) | K16: =IF(B16="","",IF(G16>=2000,20,IF(G16>=1000,10,0)))
... A504: =IF(B504="","",ROW()-4) | C504: =IF(B504="","",IFERROR(VLOOKUP(B504,'📦产品库'!$B$4:$D$9999,2,0),"⚠️未找到")) | D504: =IF(B504="","",IFERROR(VLOOKUP(B504,'📦产品库'!$B$4:$E$9999,4,0),"")) | E504: =IF(B504="","",IFERROR(VLOOKUP(B504,'📦产品库'!$B$4:$F$9999,5,0),"")) | F504: =IF(B504="","",IFERROR(VLOOKUP(B504,'📦产品库'!$B$4:$G$9999,6,0),"")) | H504: =IF(B504="","",1) | I504: =IF(B504="","",IF(G504<>"",G504*H504,F504*H504)) | K504: =IF(B504="","",IF(G504>=2000,20,IF(G504>=1000,10,0)))
A505: 当日合计 | H505: =SUM(H5:H504) | I505: =SUM(I5:I504) | K505: =MIN(SUM(K5:K504),40)

Sheet 💰薪资计算
A1: 💰 薪资计算 | 日薪阶梯 + 阶梯提成 + 大单奖励
A2: 📌 参数区（黄色格子可修改） | 蓝色格子为自动计算结果，请勿手动填写
A3: ── 薪资参数设置 ── | G3: ── 提成阶梯（按当日店铺总销售额） ──
A4: 统计月份： | B4: 2026-04 | C4: 日薪说明： • 新手期（入职~2周）：¥260/天 • 稳定期（满2周后）：¥280/天 • 熟练期（稳定达标满2周）：¥300/天 达标标准： • 周中日均 ≥ 2200–2600 • 周末/活动日 ≥ 6500–8000 经营底线： • 周中持续低于1200需复盘 • 周末持续低于4000需复盘 | G4: 销售区间下限(¥) | H4: 销售区间上限(¥) | I4: 提成比例 | J4: 说明
A5: 店员A姓名： | B5: 店员A | G5: 0 | H5: 3000 | I5: 0.02 | J5: 0–3000
A6: 店员B姓名： | B6: 店员B | G6: 3000 | H6: 6000 | I6: 0.025 | J6: 3001–6000
A7: 新手期日薪(¥)： | B7: 260 | G7: 6000 | H7: 10000 | I7: 0.03 | J7: 6001–10000
A8: 稳定期日薪(¥)： | B8: 280 | G8: 10000 | H8: 无上限 | I8: 0.04 | J8: 10000以上
A9: 熟练期日薪(¥)： | B9: 300 | G9: 提成分配规则： • 一人当班：提成全部归个人 • 两人当班：提成池平均分配 • 我(老板)和小何不参与提成 大单奖励（归成交人，不平分）： • 单笔 ≥1000：+¥10 • 单笔 ≥2000：+¥20（取最高档） • 每日最多计2笔大单
A10: 大单奖励≥1000(¥)： | B10: 10
A11: 大单奖励≥2000(¥)： | B11: 20
A12: 每日大单上限(笔)： | B12: 2
A14: ── 每日销售明细（手动录入当日数据） ──
A15: 日期 | B15: 星期 | C15: 当班 人员 | D15: 当班 人数 | E15: 店铺 总销售额(¥) | F15: 提成池(¥) | G15: 人均 提成(¥) | H15: 店员A 大单奖励(¥) | I15: 店员B 大单奖励(¥) | J15: 店员A 日薪档(¥) | K15: 店员B 日薪档(¥) | L15: 备注/达标情况
B16: =IF(A16="","",TEXT(A16,"AAA")) | D16: =IF(C16="","",IF(ISERROR(FIND(",",C16)),1,LEN(C16)-LEN(SUBSTITUTE(C16,",",""))+1)) | F16: =IF(E16="","",IF(E16<=0,0,IF(E16<=3000,E16*0.02,IF(E16<=6000,E16*0.025,IF(E16<=10000,E16*0.03,E16*0.04))))) | G16: =IF(OR(E16="",D16=""),"",IFERROR(F16/D16,F16)) | J16: 260 | K16: 260
B17: =IF(A17="","",TEXT(A17,"AAA")) | D17: =IF(C17="","",IF(ISERROR(FIND(",",C17)),1,LEN(C17)-LEN(SUBSTITUTE(C17,",",""))+1)) | F17: =IF(E17="","",IF(E17<=0,0,IF(E17<=3000,E17*0.02,IF(E17<=6000,E17*0.025,IF(E17<=10000,E17*0.03,E17*0.04))))) | G17: =IF(OR(E17="",D17=""),"",IFERROR(F17/D17,F17)) | J17: 260 | K17: 260
B18: =IF(A18="","",TEXT(A18,"AAA")) | D18: =IF(C18="","",IF(ISERROR(FIND(",",C18)),1,LEN(C18)-LEN(SUBSTITUTE(C18,",",""))+1)) | F18: =IF(E18="","",IF(E18<=0,0,IF(E18<=3000,E18*0.02,IF(E18<=6000,E18*0.025,IF(E18<=10000,E18*0.03,E18*0.04))))) | G18: =IF(OR(E18="",D18=""),"",IFERROR(F18/D18,F18)) | J18: 260 | K18: 260
B19: =IF(A19="","",TEXT(A19,"AAA")) | D19: =IF(C19="","",IF(ISERROR(FIND(",",C19)),1,LEN(C19)-LEN(SUBSTITUTE(C19,",",""))+1)) | F19: =IF(E19="","",IF(E19<=0,0,IF(E19<=3000,E19*0.02,IF(E19<=6000,E19*0.025,IF(E19<=10000,E19*0.03,E19*0.04))))) | G19: =IF(OR(E19="",D19=""),"",IFERROR(F19/D19,F19)) | J19: 260 | K19: 260
B20: =IF(A20="","",TEXT(A20,"AAA")) | D20: =IF(C20="","",IF(ISERROR(FIND(",",C20)),1,LEN(C20)-LEN(SUBSTITUTE(C20,",",""))+1)) | F20: =IF(E20="","",IF(E20<=0,0,IF(E20<=3000,E20*0.02,IF(E20<=6000,E20*0.025,IF(E20<=10000,E20*0.03,E20*0.04))))) | G20: =IF(OR(E20="",D20=""),"",IFERROR(F20/D20,F20)) | J20: 260 | K20: 260
B21: =IF(A21="","",TEXT(A21,"AAA")) | D21: =IF(C21="","",IF(ISERROR(FIND(",",C21)),1,LEN(C21)-LEN(SUBSTITUTE(C21,",",""))+1)) | F21: =IF(E21="","",IF(E21<=0,0,IF(E21<=3000,E21*0.02,IF(E21<=6000,E21*0.025,IF(E21<=10000,E21*0.03,E21*0.04))))) | G21: =IF(OR(E21="",D21=""),"",IFERROR(F21/D21,F21)) | J21: 260 | K21: 260
B22: =IF(A22="","",TEXT(A22,"AAA")) | D22: =IF(C22="","",IF(ISERROR(FIND(",",C22)),1,LEN(C22)-LEN(SUBSTITUTE(C22,",",""))+1)) | F22: =IF(E22="","",IF(E22<=0,0,IF(E22<=3000,E22*0.02,IF(E22<=6000,E22*0.025,IF(E22<=10000,E22*0.03,E22*0.04))))) | G22: =IF(OR(E22="",D22=""),"",IFERROR(F22/D22,F22)) | J22: 260 | K22: 260
B23: =IF(A23="","",TEXT(A23,"AAA")) | D23: =IF(C23="","",IF(ISERROR(FIND(",",C23)),1,LEN(C23)-LEN(SUBSTITUTE(C23,",",""))+1)) | F23: =IF(E23="","",IF(E23<=0,0,IF(E23<=3000,E23*0.02,IF(E23<=6000,E23*0.025,IF(E23<=10000,E23*0.03,E23*0.04))))) | G23: =IF(OR(E23="",D23=""),"",IFERROR(F23/D23,F23)) | J23: 260 | K23: 260
B24: =IF(A24="","",TEXT(A24,"AAA")) | D24: =IF(C24="","",IF(ISERROR(FIND(",",C24)),1,LEN(C24)-LEN(SUBSTITUTE(C24,",",""))+1)) | F24: =IF(E24="","",IF(E24<=0,0,IF(E24<=3000,E24*0.02,IF(E24<=6000,E24*0.025,IF(E24<=10000,E24*0.03,E24*0.04))))) | G24: =IF(OR(E24="",D24=""),"",IFERROR(F24/D24,F24)) | J24: 260 | K24: 260
B25: =IF(A25="","",TEXT(A25,"AAA")) | D25: =IF(C25="","",IF(ISERROR(FIND(",",C25)),1,LEN(C25)-LEN(SUBSTITUTE(C25,",",""))+1)) | F25: =IF(E25="","",IF(E25<=0,0,IF(E25<=3000,E25*0.02,IF(E25<=6000,E25*0.025,IF(E25<=10000,E25*0.03,E25*0.04))))) | G25: =IF(OR(E25="",D25=""),"",IFERROR(F25/D25,F25)) | J25: 260 | K25: 260
B26: =IF(A26="","",TEXT(A26,"AAA")) | D26: =IF(C26="","",IF(ISERROR(FIND(",",C26)),1,LEN(C26)-LEN(SUBSTITUTE(C26,",",""))+1)) | F26: =IF(E26="","",IF(E26<=0,0,IF(E26<=3000,E26*0.02,IF(E26<=6000,E26*0.025,IF(E26<=10000,E26*0.03,E26*0.04))))) | G26: =IF(OR(E26="",D26=""),"",IFERROR(F26/D26,F26)) | J26: 260 | K26: 260
B27: =IF(A27="","",TEXT(A27,"AAA")) | D27: =IF(C27="","",IF(ISERROR(FIND(",",C27)),1,LEN(C27)-LEN(SUBSTITUTE(C27,",",""))+1)) | F27: =IF(E27="","",IF(E27<=0,0,IF(E27<=3000,E27*0.02,IF(E27<=6000,E27*0.025,IF(E27<=10000,E27*0.03,E27*0.04))))) | G27: =IF(OR(E27="",D27=""),"",IFERROR(F27/D27,F27)) | J27: 260 | K27: 260
... B46: =IF(A46="","",TEXT(A46,"AAA")) | D46: =IF(C46="","",IF(ISERROR(FIND(",",C46)),1,LEN(C46)-LEN(SUBSTITUTE(C46,",",""))+1)) | F46: =IF(E46="","",IF(E46<=0,0,IF(E46<=3000,E46*0.02,IF(E46<=6000,E46*0.025,IF(E46<=10000,E46*0.03,E46*0.04))))) | G46: =IF(OR(E46="",D46=""),"",IFERROR(F46/D46,F46)) | J46: 260 | K46: 260
A47: ── 月末汇总 ──
A48: 月总销售额 | B48: =SUM(E16:E46) | C48: 月提成池 | D48: =SUM(F16:F46)
A49: 店员A当月应发 | B49: =SUM(J16:J46)+SUM(G16:G46)+SUM(H16:H46) | C49: ⚠️ 说明：当月应发 = Σ日薪 + Σ人均提成（仅当班日计入）+ 大单奖励 人均提成列(G列)已按当班人数平分。两人同班时两人各拿一份，单人班全拿。 大单奖励按成交人归属（H列=店员A，I列=店员B），不参与平分。
A50: 店员B当月应发 | B50: =SUM(K16:K46)+SUM(G16:G46)+SUM(I16:I46)

Sheet 📊库存管理
A1: 📊 库存管理 | 月度盘点
A2: 💡 期末 = 期初 + 入库 - 销售 | 库存≤2件标黄预警，0件标红
A3: 统计月份： | B3: 2026-04
A4: 序号 | B4: 货号(SKU) | C4: 商品名称 | D4: 颜色 | E4: 尺码 | F4: 售价(¥) | G4: 期初库存 | H4: 本月入库 | I4: 本月销售 | J4: 期末库存 | K4: 库存状态 | L4: 备注
A5: 1 | B5: NS2614-L | C5: 扭捏niunie 复古格子全羊毛格子外套七分袖短裤宽松衬衫上衣女 | D5: 七分袖格子毛呢外套 | E5: L | F5: 799 | G5: 6 | H5: 0 | I5: 0 | J5: =G5+H5-I5 | K5: =IF(J5=0,"🔴缺货",IF(J5<=2,"🟡低库存","🟢正常"))
A6: 2 | B6: NS2614-M | C6: 扭捏niunie 复古格子全羊毛格子外套七分袖短裤宽松衬衫上衣女 | D6: 七分袖格子毛呢外套 | E6: M | F6: 799 | G6: 1 | H6: 0 | I6: 0 | J6: =G6+H6-I6 | K6: =IF(J6=0,"🔴缺货",IF(J6<=2,"🟡低库存","🟢正常"))
A7: 3 | B7: NS2614-S | C7: 扭捏niunie 复古格子全羊毛格子外套七分袖短裤宽松衬衫上衣女 | D7: 七分袖格子毛呢外套 | E7: S | F7: 799 | G7: 0 | H7: 0 | I7: 0 | J7: =G7+H7-I7 | K7: =IF(J7=0,"🔴缺货",IF(J7<=2,"🟡低库存","🟢正常"))
A8: 4 | B8: NS2613-M | C8: 扭捏niunie 黄色小碎花两面穿半身裙女打褶中长款甜美A字伞裙夏季 | D8: 黄色小碎花两面穿半身裙 | E8: M | F8: 439 | G8: 4 | H8: 0 | I8: 0 | J8: =G8+H8-I8 | K8: =IF(J8=0,"🔴缺货",IF(J8<=2,"🟡低库存","🟢正常"))
A9: 5 | B9: NS2613-S | C9: 扭捏niunie 黄色小碎花两面穿半身裙女打褶中长款甜美A字伞裙夏季 | D9: 黄色小碎花两面穿半身裙 | E9: S | F9: 439 | G9: 2 | H9: 0 | I9: 0 | J9: =G9+H9-I9 | K9: =IF(J9=0,"🔴缺货",IF(J9<=2,"🟡低库存","🟢正常"))
A10: 6 | B10: NS2611-M | C10: 扭捏niunie甜美清新花边口袋樱桃提花拼接圆领短袖衬衫花苞裤套装 | D10: 樱桃提花有口袋衬衫 | E10: M | F10: 369 | G10: 23 | H10: 0 | I10: 0 | J10: =G10+H10-I10 | K10: =IF(J10=0,"🔴缺货",IF(J10<=2,"🟡低库存","🟢正常"))
A11: 7 | B11: NS2612-M | C11: 扭捏niunie甜美清新花边口袋樱桃提花拼接圆领短袖衬衫花苞裤套装 | D11: 樱桃花苞裤 | E11: M | F11: 329 | G11: 2 | H11: 0 | I11: 0 | J11: =G11+H11-I11 | K11: =IF(J11=0,"🔴缺货",IF(J11<=2,"🟡低库存","🟢正常"))
A12: 8 | B12: NS2611-S | C12: 扭捏niunie甜美清新花边口袋樱桃提花拼接圆领短袖衬衫花苞裤套装 | D12: 樱桃提花有口袋衬衫 | E12: S | F12: 369 | G12: 11 | H12: 0 | I12: 0 | J12: =G12+H12-I12 | K12: =IF(J12=0,"🔴缺货",IF(J12<=2,"🟡低库存","🟢正常"))
A13: 9 | B13: NS2612-S | C13: 扭捏niunie甜美清新花边口袋樱桃提花拼接圆领短袖衬衫花苞裤套装 | D13: 樱桃花苞裤 | E13: S | F13: 329 | G13: 0 | H13: 0 | I13: 0 | J13: =G13+H13-I13 | K13: =IF(J13=0,"🔴缺货",IF(J13<=2,"🟡低库存","🟢正常"))
A14: 10 | B14: NS2610-M | C14: 扭捏niunie 亚麻复古彩色格子荷叶边短裙抽褶拼接修身半身裙女 | D14: 彩色亚麻格子短裙 | E14: M | F14: 529 | G14: 10 | H14: 0 | I14: 0 | J14: =G14+H14-I14 | K14: =IF(J14=0,"🔴缺货",IF(J14<=2,"🟡低库存","🟢正常"))
A15: 11 | B15: NS2610-S | C15: 扭捏niunie 亚麻复古彩色格子荷叶边短裙抽褶拼接修身半身裙女 | D15: 彩色亚麻格子短裙 | E15: S | F15: 529 | G15: 10 | H15: 0 | I15: 0 | J15: =G15+H15-I15 | K15: =IF(J15=0,"🔴缺货",IF(J15<=2,"🟡低库存","🟢正常"))
A16: 12 | B16: NS2609-M | C16: 扭捏niunie 青苹果天使十字绣针织衫长袖圆领T恤甜美宽松上衣女 | D16: 青苹果天使针织长袖t | E16: M | F16: 199 | G16: 22 | H16: 0 | I16: 0 | J16: =G16+H16-I16 | K16: =IF(J16=0,"🔴缺货",IF(J16<=2,"🟡低库存","🟢正常"))
... A79: 75 | B79: NN2533-L | C79: 【秋天的童话】原创巴恩风剪花小格子重工半身裙复古中长裙女秋款 | D79: 彩色剪花小格子半身裙 | E79: L | F79: 429 | G79: 15 | H79: 0 | I79: 0 | J79: =G79+H79-I79 | K79: =IF(J79=0,"🔴缺货",IF(J79<=2,"🟡低库存","🟢正常"))
A80: 76 | C80: 扭捏niunie 小浣熊松鼠趣味提花蓝色长袖衬衫宽松全棉纽扣上衣女 | D80: 定制面料 需要等待 | E80: M | F80: 339 | G80: 4 | H80: 0 | I80: 0 | J80: =G80+H80-I80 | K80: =IF(J80=0,"🔴缺货",IF(J80<=2,"🟡低库存","🟢正常"))
A81: 77 | C81: 扭捏niunie 小浣熊松鼠趣味提花蓝色长袖衬衫宽松全棉纽扣上衣女 | D81: 定制面料 需要等待 | E81: S | F81: 339 | G81: 8 | H81: 0 | I81: 0 | J81: =G81+H81-I81 | K81: =IF(J81=0,"🔴缺货",IF(J81<=2,"🟡低库存","🟢正常"))
A82: 78 | C82: 扭捏niunie 多巴胺提花蓝色慵懒风休闲长裤宽松显瘦百搭直筒裤女 | D82: 定制面料 需要等待 | E82: M | F82: 319 | G82: 1 | H82: 0 | I82: 0 | J82: =G82+H82-I82 | K82: =IF(J82=0,"🔴缺货",IF(J82<=2,"🟡低库存","🟢正常"))
A83: 79 | C83: 扭捏niunie 多巴胺提花蓝色慵懒风休闲长裤宽松显瘦百搭直筒裤女 | D83: 定制面料 需要等待 | E83: S | F83: 319 | G83: 0 | H83: 0 | I83: 0 | J83: =G83+H83-I83 | K83: =IF(J83=0,"🔴缺货",IF(J83<=2,"🟡低库存","🟢正常"))
A84: 80 | B84: TNW-0702-褐L | C84: 扭捏niunie 乐谱印花复古长袖T恤进口美利奴羊毛天丝修身内搭上衣 | D84: 茶褐色天丝羊毛长袖t | E84: L | F84: 299 | G84: 2 | H84: 0 | I84: 0 | J84: =G84+H84-I84 | K84: =IF(J84=0,"🔴缺货",IF(J84<=2,"🟡低库存","🟢正常"))
A85: 81 | B85: TNW-0702-绿L | C85: 扭捏niunie 乐谱印花复古长袖T恤进口美利奴羊毛天丝修身内搭上衣 | D85: 草绿色天丝羊毛长袖t | E85: L | F85: 299 | G85: 5 | H85: 0 | I85: 0 | J85: =G85+H85-I85 | K85: =IF(J85=0,"🔴缺货",IF(J85<=2,"🟡低库存","🟢正常"))
A86: 82 | B86: TNW-0702-褐M | C86: 扭捏niunie 乐谱印花复古长袖T恤进口美利奴羊毛天丝修身内搭上衣 | D86: 茶褐色天丝羊毛长袖t | E86: M | F86: 299 | G86: 3 | H86: 0 | I86: 0 | J86: =G86+H86-I86 | K86: =IF(J86=0,"🔴缺货",IF(J86<=2,"🟡低库存","🟢正常"))
A87: 83 | B87: TNW-0702-绿M | C87: 扭捏niunie 乐谱印花复古长袖T恤进口美利奴羊毛天丝修身内搭上衣 | D87: 草绿色天丝羊毛长袖t | E87: M | F87: 299 | G87: 7 | H87: 0 | I87: 0 | J87: =G87+H87-I87 | K87: =IF(J87=0,"🔴缺货",IF(J87<=2,"🟡低库存","🟢正常"))
A88: 84 | B88: TNW-0702-褐S | C88: 扭捏niunie 乐谱印花复古长袖T恤进口美利奴羊毛天丝修身内搭上衣 | D88: 茶褐色天丝羊毛长袖t | E88: S | F88: 299 | G88: 3 | H88: 0 | I88: 0 | J88: =G88+H88-I88 | K88: =IF(J88=0,"🔴缺货",IF(J88<=2,"🟡低库存","🟢正常"))
A89: 85 | B89: TNW-0702-绿S | C89: 扭捏niunie 乐谱印花复古长袖T恤进口美利奴羊毛天丝修身内搭上衣 | D89: 草绿色天丝羊毛长袖t | E89: S | F89: 299 | G89: 10 | H89: 0 | I89: 0 | J89: =G89+H89-I89 | K89: =IF(J89=0,"🔴缺货",IF(J89<=2,"🟡低库存","🟢正常"))
A90: 86 | B90: TNW-0915-M | C90: 扭捏niunie法式复古撞色拼接衬衫澳洲进口美利奴羊毛缩绒工艺上衣 | D90: 浅绿色花苞裙 | E90: M | F90: 499 | G90: 3 | H90: 0 | I90: 0 | J90: =G90+H90-I90 | K90: =IF(J90=0,"🔴缺货",IF(J90<=2,"🟡低库存","🟢正常"))
A91: 87 | B91: TNW-0915-S | C91: 扭捏niunie法式复古撞色拼接衬衫澳洲进口美利奴羊毛缩绒工艺上衣 | D91: 浅绿色花苞裙 | E91: S | F91: 499 | G91: 3 | H91: 0 | I91: 0 | J91: =G91+H91-I91 | K91: =IF(J91=0,"🔴缺货",IF(J91<=2,"🟡低库存","🟢正常"))
A92: 88 | B92: TNW-1010-M | C92: 扭捏niunie 复古vintage格子碎花拼接半身裙修身显瘦田园风中长裙 | D92: 格子碎花拼接半裙 | E92: M | F92: 439 | G92: 4 | H92: 0 | I92: 0 | J92: =G92+H92-I92 | K92: =IF(J92=0,"🔴缺货",IF(J92<=2,"🟡低库存","🟢正常"))
A93: 89 | B93: TNW-1010-S | C93: 扭捏niunie 复古vintage格子碎花拼接半身裙修身显瘦田园风中长裙 | D93: 格子碎花拼接半裙 | E93: S | F93: 439 | G93: 6 | H93: 0 | I93: 0 | J93: =G93+H93-I93 | K93: =IF(J93=0,"🔴缺货",IF(J93<=2,"🟡低库存","🟢正常"))
A94: 90 | B94: TNW-0918-M | C94: 【我只想睡觉】原创印花圆领毛巾卫衣复古宽松上衣 扭捏niunie | D94: 撞色圆领卫衣 | E94: M | F94: 299 | G94: 7 | H94: 0 | I94: 0 | J94: =G94+H94-I94 | K94: =IF(J94=0,"🔴缺货",IF(J94<=2,"🟡低库存","🟢正常"))
A95: 91 | B95: TNW-0918-S | C95: 【我只想睡觉】原创印花圆领毛巾卫衣复古宽松上衣 扭捏niunie | D95: 撞色圆领卫衣 | E95: S | F95: 299 | G95: 11 | H95: 0 | I95: 0 | J95: =G95+H95-I95 | K95: =IF(J95=0,"🔴缺货",IF(J95<=2,"🟡低库存","🟢正常"))
... A111: 107 | B111: NN2537-S | C111: 扭捏niunie 复古休闲翻领牛仔外套格子拼接A字半裙全棉高级感套装 | D111: 牛仔外套 | E111: S | F111: 369 | G111: 0 | H111: 0 | I111: 0 | J111: =G111+H111-I111 | K111: =IF(J111=0,"🔴缺货",IF(J111<=2,"🟡低库存","🟢正常"))
A112: 108 | C112: 扭捏niunie 复古vintage宽松慵懒感上衣 果实扣100%苎麻衬衫夏季 | D112: 黄色 | E112: L | F112: 398 | G112: 11 | H112: 0 | I112: 0 | J112: =G112+H112-I112 | K112: =IF(J112=0,"🔴缺货",IF(J112<=2,"🟡低库存","🟢正常"))
A113: 109 | C113: 扭捏niunie 复古vintage宽松慵懒感上衣 果实扣100%苎麻衬衫夏季 | D113: 黄色 | E113: M | F113: 398 | G113: 25 | H113: 0 | I113: 0 | J113: =G113+H113-I113 | K113: =IF(J113=0,"🔴缺货",IF(J113<=2,"🟡低库存","🟢正常"))
A114: 110 | C114: 扭捏niunie 复古vintage宽松慵懒感上衣 果实扣100%苎麻衬衫夏季 | D114: 黄色 | E114: S | F114: 398 | G114: 16 | H114: 0 | I114: 0 | J114: =G114+H114-I114 | K114: =IF(J114=0,"🔴缺货",IF(J114<=2,"🟡低库存","🟢正常"))
A115: 111 | B115: NTF0311W-1-L | C115: 扭捏 少女的祈祷 花边拼接蛋糕a字小短裙白色半身裙 防走光内衬 | D115: 白色拼接短裙 （绗缝位置改版） | E115: L | F115: 338 | G115: 13 | H115: 0 | I115: 0 | J115: =G115+H115-I115 | K115: =IF(J115=0,"🔴缺货",IF(J115<=2,"🟡低库存","🟢正常"))
A116: 112 | B116: NTF0311W-1-M | C116: 扭捏 少女的祈祷 花边拼接蛋糕a字小短裙白色半身裙 防走光内衬 | D116: 白色拼接短裙 （绗缝位置改版） | E116: M | F116: 338 | G116: 17 | H116: 0 | I116: 0 | J116: =G116+H116-I116 | K116: =IF(J116=0,"🔴缺货",IF(J116<=2,"🟡低库存","🟢正常"))
A117: 113 | B117: NTF0311W-1-S | C117: 扭捏 少女的祈祷 花边拼接蛋糕a字小短裙白色半身裙 防走光内衬 | D117: 白色拼接短裙 （绗缝位置改版） | E117: S | F117: 338 | G117: 13 | H117: 0 | I117: 0 | J117: =G117+H117-I117 | K117: =IF(J117=0,"🔴缺货",IF(J117<=2,"🟡低库存","🟢正常"))
...

Sheet 📥入库记录
A1: 📥 入库记录 | 每次到货登记
A2: 💡 每次到货后在此记录 | 填完后手动更新【库存管理】的本月入库列
A3: 序号 | B3: 入库日期 | C3: 货号(SKU) | D3: 商品名称 | E3: 颜色规格 | F3: 入库数量 | G3: 供应商/备注 | H3: 经手人
A4: =IF(B4="","",ROW()-3)
A5: =IF(B5="","",ROW()-3)
A6: =IF(B6="","",ROW()-3)
A7: =IF(B7="","",ROW()-3)
A8: =IF(B8="","",ROW()-3)
A9: =IF(B9="","",ROW()-3)
A10: =IF(B10="","",ROW()-3)
A11: =IF(B11="","",ROW()-3)
A12: =IF(B12="","",ROW()-3)
A13: =IF(B13="","",ROW()-3)
A14: =IF(B14="","",ROW()-3)
A15: =IF(B15="","",ROW()-3)
... A203: =IF(B203="","",ROW()-3)

Sheet 📈月度汇总
A1: 📈 月度汇总 | 全年经营一览
A2: 月份 | B2: 销售天数 | C2: 月总销售额(¥) | D2: 销售件数 | E2: 店员A工资(¥) | F2: 店员B工资(¥) | G2: 提成合计(¥) | H2: 经营达标情况 | I2: 备注
A3: 2026-01
A4: 2026-02
A5: 2026-03
A6: 2026-04
A7: 2026-05
A8: 2026-06
A9: 2026-07
A10: 2026-08
A11: 2026-09
A12: 2026-10
A13: 2026-11
A14: 2026-12

Sheet 🚚补货导出
A1: 🚚 补货导出 | 基于库存自动生成补货清单，发给仓库补货
A2: 💡 补货数量 = 建议库存 - 期末库存（自动算）| 建议库存可修改 | 复制数据区发给仓库即可
A3: 序号 | B3: 货号(SKU) | C3: 款式编码 | D3: 商品名称 | E3: 颜色 | F3: 尺码 | G3: 售价(¥) | H3: 当前库存 | I3: 建议库存 | J3: 补货数量 | K3: 图片链接 | L3: 供应商/备注
A4: 1 | B4: NS2614-L | C4: NS2614 | D4: 扭捏niunie 复古格子全羊毛格子外套七分袖短裤宽松衬衫上衣女 | E4: 七分袖格子毛呢外套 | F4: L | G4: 799 | H4: 6 | I4: 3 | J4: =MAX(I4-H4,0) | K4: https://img.alicdn.com/bao/uploaded/i1/2217590670593/O1CN014SZXqr1GFdzaJafbf~crop,0,57,1440,1440~_!!2217590670593.jpg
A5: 2 | B5: NS2614-M | C5: NS2614 | D5: 扭捏niunie 复古格子全羊毛格子外套七分袖短裤宽松衬衫上衣女 | E5: 七分袖格子毛呢外套 | F5: M | G5: 799 | H5: 1 | I5: 3 | J5: =MAX(I5-H5,0) | K5: https://img.alicdn.com/bao/uploaded/i1/2217590670593/O1CN014SZXqr1GFdzaJafbf~crop,0,57,1440,1440~_!!2217590670593.jpg
A6: 3 | B6: NS2614-S | C6: NS2614 | D6: 扭捏niunie 复古格子全羊毛格子外套七分袖短裤宽松衬衫上衣女 | E6: 七分袖格子毛呢外套 | F6: S | G6: 799 | H6: 0 | I6: 3 | J6: =MAX(I6-H6,0) | K6: https://img.alicdn.com/bao/uploaded/i1/2217590670593/O1CN014SZXqr1GFdzaJafbf~crop,0,57,1440,1440~_!!2217590670593.jpg
A7: 4 | B7: NS2613-M | C7: NS2613 | D7: 扭捏niunie 黄色小碎花两面穿半身裙女打褶中长款甜美A字伞裙夏季 | E7: 黄色小碎花两面穿半身裙 | F7: M | G7: 439 | H7: 4 | I7: 3 | J7: =MAX(I7-H7,0) | K7: https://img.alicdn.com/bao/uploaded/i3/2217590670593/O1CN013VOeEz1GFdzbUPeAA~crop,0,240,1440,1440~_!!2217590670593.jpg
A8: 5 | B8: NS2613-S | C8: NS2613 | D8: 扭捏niunie 黄色小碎花两面穿半身裙女打褶中长款甜美A字伞裙夏季 | E8: 黄色小碎花两面穿半身裙 | F8: S | G8: 439 | H8: 2 | I8: 3 | J8: =MAX(I8-H8,0) | K8: https://img.alicdn.com/bao/uploaded/i3/2217590670593/O1CN013VOeEz1GFdzbUPeAA~crop,0,240,1440,1440~_!!2217590670593.jpg
A9: 6 | B9: NS2611-M | C9: NS2611+NS2612 | D9: 扭捏niunie甜美清新花边口袋樱桃提花拼接圆领短袖衬衫花苞裤套装 | E9: 樱桃提花有口袋衬衫 | F9: M | G9: 369 | H9: 23 | I9: 3 | J9: =MAX(I9-H9,0) | K9: https://img.alicdn.com/bao/uploaded/i2/2217590670593/O1CN01xgSwHZ1GFdzaMGyRv~crop,0,240,1440,1440~_!!2217590670593.jpg
A10: 7 | B10: NS2612-M | C10: NS2611+NS2612 | D10: 扭捏niunie甜美清新花边口袋樱桃提花拼接圆领短袖衬衫花苞裤套装 | E10: 樱桃花苞裤 | F10: M | G10: 329 | H10: 2 | I10: 3 | J10: =MAX(I10-H10,0) | K10: https://img.alicdn.com/bao/uploaded/i2/2217590670593/O1CN01CHDMQM1GFdzZvCfJO~crop,0,240,1440,1440~_!!2217590670593.jpg
A11: 8 | B11: NS2611-S | C11: NS2611+NS2612 | D11: 扭捏niunie甜美清新花边口袋樱桃提花拼接圆领短袖衬衫花苞裤套装 | E11: 樱桃提花有口袋衬衫 | F11: S | G11: 369 | H11: 11 | I11: 3 | J11: =MAX(I11-H11,0) | K11: https://img.alicdn.com/bao/uploaded/i2/2217590670593/O1CN01xgSwHZ1GFdzaMGyRv~crop,0,240,1440,1440~_!!2217590670593.jpg
A12: 9 | B12: NS2612-S | C12: NS2611+NS2612 | D12: 扭捏niunie甜美清新花边口袋樱桃提花拼接圆领短袖衬衫花苞裤套装 | E12: 樱桃花苞裤 | F12: S | G12: 329 | H12: 0 | I12: 3 | J12: =MAX(I12-H12,0) | K12: https://img.alicdn.com/bao/uploaded/i2/2217590670593/O1CN01CHDMQM1GFdzZvCfJO~crop,0,240,1440,1440~_!!2217590670593.jpg
A13: 10 | B13: NS2610-M | C13: NS2610 | D13: 扭捏niunie 亚麻复古彩色格子荷叶边短裙抽褶拼接修身半身裙女 | E13: 彩色亚麻格子短裙 | F13: M | G13: 529 | H13: 10 | I13: 3 | J13: =MAX(I13-H13,0) | K13: https://img.alicdn.com/bao/uploaded/i3/2217590670593/O1CN01o0MRbu1GFdza9nw57~crop,0,240,1440,1440~_!!2217590670593.jpg
A14: 11 | B14: NS2610-S | C14: NS2610 | D14: 扭捏niunie 亚麻复古彩色格子荷叶边短裙抽褶拼接修身半身裙女 | E14: 彩色亚麻格子短裙 | F14: S | G14: 529 | H14: 10 | I14: 3 | J14: =MAX(I14-H14,0) | K14: https://img.alicdn.com/bao/uploaded/i3/2217590670593/O1CN01o0MRbu1GFdza9nw57~crop,0,240,1440,1440~_!!2217590670593.jpg
A15: 12 | B15: NS2609-M | C15: NS2609 | D15: 扭捏niunie 青苹果天使十字绣针织衫长袖圆领T恤甜美宽松上衣女 | E15: 青苹果天使针织长袖t | F15: M | G15: 199 | H15: 22 | I15: 3 | J15: =MAX(I15-H15,0) | K15: https://img.alicdn.com/bao/uploaded/i4/2217590670593/O1CN01oHujxO1GFdzZY3erp~crop,0,240,1440,1440~_!!2217590670593.jpg
... A78: 75 | B78: NN2533-L | C78: NN2533 | D78: 【秋天的童话】原创巴恩风剪花小格子重工半身裙复古中长裙女秋款 | E78: 彩色剪花小格子半身裙 | F78: L | G78: 429 | H78: 15 | I78: 3 | J78: =MAX(I78-H78,0) | K78: https://img.alicdn.com/bao/uploaded/i4/2217590670593/O1CN01g52yMQ1GFdx0brzbm_!!2217590670593.jpg
A79: 76 | C79: NN2530 | D79: 扭捏niunie 小浣熊松鼠趣味提花蓝色长袖衬衫宽松全棉纽扣上衣女 | E79: 定制面料 需要等待 | F79: M | G79: 339 | H79: 4 | I79: 3 | J79: =MAX(I79-H79,0) | K79: https://img.alicdn.com/bao/uploaded/i3/2217590670593/O1CN01RZwv0i1GFdxBBivtA_!!2217590670593.jpg
A80: 77 | C80: NN2530 | D80: 扭捏niunie 小浣熊松鼠趣味提花蓝色长袖衬衫宽松全棉纽扣上衣女 | E80: 定制面料 需要等待 | F80: S | G80: 339 | H80: 8 | I80: 3 | J80: =MAX(I80-H80,0) | K80: https://img.alicdn.com/bao/uploaded/i3/2217590670593/O1CN01RZwv0i1GFdxBBivtA_!!2217590670593.jpg
A81: 78 | C81: NN2536 | D81: 扭捏niunie 多巴胺提花蓝色慵懒风休闲长裤宽松显瘦百搭直筒裤女 | E81: 定制面料 需要等待 | F81: M | G81: 319 | H81: 1 | I81: 3 | J81: =MAX(I81-H81,0) | K81: https://img.alicdn.com/bao/uploaded/i3/2217590670593/O1CN01RZwv0i1GFdxBBivtA_!!2217590670593.jpg
A82: 79 | C82: NN2536 | D82: 扭捏niunie 多巴胺提花蓝色慵懒风休闲长裤宽松显瘦百搭直筒裤女 | E82: 定制面料 需要等待 | F82: S | G82: 319 | H82: 0 | I82: 3 | J82: =MAX(I82-H82,0) | K82: https://img.alicdn.com/bao/uploaded/i3/2217590670593/O1CN01RZwv0i1GFdxBBivtA_!!2217590670593.jpg
A83: 80 | B83: TNW-0702-褐L | C83: TNW-0702 | D83: 扭捏niunie 乐谱印花复古长袖T恤进口美利奴羊毛天丝修身内搭上衣 | E83: 茶褐色天丝羊毛长袖t | F83: L | G83: 299 | H83: 2 | I83: 3 | J83: =MAX(I83-H83,0) | K83: https://img.alicdn.com/bao/uploaded/i4/2217590670593/O1CN01yjUReo1GFdx1hYVgl_!!2217590670593.jpg
A84: 81 | B84: TNW-0702-绿L | C84: TNW-0702 | D84: 扭捏niunie 乐谱印花复古长袖T恤进口美利奴羊毛天丝修身内搭上衣 | E84: 草绿色天丝羊毛长袖t | F84: L | G84: 299 | H84: 5 | I84: 3 | J84: =MAX(I84-H84,0) | K84: https://img.alicdn.com/bao/uploaded/i1/2217590670593/O1CN019qHJlo1GFdx12brW4_!!2217590670593.jpg
A85: 82 | B85: TNW-0702-褐M | C85: TNW-0702 | D85: 扭捏niunie 乐谱印花复古长袖T恤进口美利奴羊毛天丝修身内搭上衣 | E85: 茶褐色天丝羊毛长袖t | F85: M | G85: 299 | H85: 3 | I85: 3 | J85: =MAX(I85-H85,0) | K85: https://img.alicdn.com/bao/uploaded/i4/2217590670593/O1CN01yjUReo1GFdx1hYVgl_!!2217590670593.jpg
A86: 83 | B86: TNW-0702-绿M | C86: TNW-0702 | D86: 扭捏niunie 乐谱印花复古长袖T恤进口美利奴羊毛天丝修身内搭上衣 | E86: 草绿色天丝羊毛长袖t | F86: M | G86: 299 | H86: 7 | I86: 3 | J86: =MAX(I86-H86,0) | K86: https://img.alicdn.com/bao/uploaded/i1/2217590670593/O1CN019qHJlo1GFdx12brW4_!!2217590670593.jpg
A87: 84 | B87: TNW-0702-褐S | C87: TNW-0702 | D87: 扭捏niunie 乐谱印花复古长袖T恤进口美利奴羊毛天丝修身内搭上衣 | E87: 茶褐色天丝羊毛长袖t | F87: S | G87: 299 | H87: 3 | I87: 3 | J87: =MAX(I87-H87,0) | K87: https://img.alicdn.com/bao/uploaded/i4/2217590670593/O1CN01yjUReo1GFdx1hYVgl_!!2217590670593.jpg
A88: 85 | B88: TNW-0702-绿S | C88: TNW-0702 | D88: 扭捏niunie 乐谱印花复古长袖T恤进口美利奴羊毛天丝修身内搭上衣 | E88: 草绿色天丝羊毛长袖t | F88: S | G88: 299 | H88: 10 | I88: 3 | J88: =MAX(I88-H88,0) | K88: https://img.alicdn.com/bao/uploaded/i1/2217590670593/O1CN019qHJlo1GFdx12brW4_!!2217590670593.jpg
A89: 86 | B89: TNW-0915-M | C89: TNW-0802 | D89: 扭捏niunie法式复古撞色拼接衬衫澳洲进口美利奴羊毛缩绒工艺上衣 | E89: 浅绿色花苞裙 | F89: M | G89: 499 | H89: 3 | I89: 3 | J89: =MAX(I89-H89,0) | K89: https://img.alicdn.com/bao/uploaded/i1/2217590670593/O1CN01wihPxS1GFdwvCQXKy_!!2217590670593.jpg
A90: 87 | B90: TNW-0915-S | C90: TNW-0802 | D90: 扭捏niunie法式复古撞色拼接衬衫澳洲进口美利奴羊毛缩绒工艺上衣 | E90: 浅绿色花苞裙 | F90: S | G90: 499 | H90: 3 | I90: 3 | J90: =MAX(I90-H90,0) | K90: https://img.alicdn.com/bao/uploaded/i1/2217590670593/O1CN01wihPxS1GFdwvCQXKy_!!2217590670593.jpg
A91: 88 | B91: TNW-1010-M | C91: TNW-1010 | D91: 扭捏niunie 复古vintage格子碎花拼接半身裙修身显瘦田园风中长裙 | E91: 格子碎花拼接半裙 | F91: M | G91: 439 | H91: 4 | I91: 3 | J91: =MAX(I91-H91,0) | K91: https://img.alicdn.com/bao/uploaded/i4/2217590670593/O1CN01eVMZOI1GFdsWomFSu_!!2217590670593.jpg
A92: 89 | B92: TNW-1010-S | C92: TNW-1010 | D92: 扭捏niunie 复古vintage格子碎花拼接半身裙修身显瘦田园风中长裙 | E92: 格子碎花拼接半裙 | F92: S | G92: 439 | H92: 6 | I92: 3 | J92: =MAX(I92-H92,0) | K92: https://img.alicdn.com/bao/uploaded/i4/2217590670593/O1CN01eVMZOI1GFdsWomFSu_!!2217590670593.jpg
A93: 90 | B93: TNW-0918-M | C93: TNW-0918 | D93: 【我只想睡觉】原创印花圆领毛巾卫衣复古宽松上衣 扭捏niunie | E93: 撞色圆领卫衣 | F93: M | G93: 299 | H93: 7 | I93: 3 | J93: =MAX(I93-H93,0) | K93: https://img.alicdn.com/bao/uploaded/i2/2217590670593/O1CN01uKNQeD1GFdwzZUDc8_!!2217590670593.jpg
A94: 91 | B94: TNW-0918-S | C94: TNW-0918 | D94: 【我只想睡觉】原创印花圆领毛巾卫衣复古宽松上衣 扭捏niunie | E94: 撞色圆领卫衣 | F94: S | G94: 299 | H94: 11 | I94: 3 | J94: =MAX(I94-H94,0) | K94: https://img.alicdn.com/bao/uploaded/i2/2217590670593/O1CN01uKNQeD1GFdwzZUDc8_!!2217590670593.jpg
... A110: 107 | B110: NN2537-S | C110: NN2537-2538 | D110: 扭捏niunie 复古休闲翻领牛仔外套格子拼接A字半裙全棉高级感套装 | E110: 牛仔外套 | F110: S | G110: 369 | H110: 0 | I110: 3 | J110: =MAX(I110-H110,0) | K110: https://img.alicdn.com/bao/uploaded/i1/2217590670593/O1CN01BnonAW1GFdwvincOo_!!2217590670593.jpg
A111: 108 | C111: NN-2515 | D111: 扭捏niunie 复古vintage宽松慵懒感上衣 果实扣100%苎麻衬衫夏季 | E111: 黄色 | F111: L | G111: 398 | H111: 11 | I111: 3 | J111: =MAX(I111-H111,0) | K111: https://img.alicdn.com/bao/uploaded/i4/2217590670593/O1CN01Z5hiwq1GFdv2jmgHC_!!2217590670593.jpg
A112: 109 | C112: NN-2515 | D112: 扭捏niunie 复古vintage宽松慵懒感上衣 果实扣100%苎麻衬衫夏季 | E112: 黄色 | F112: M | G112: 398 | H112: 25 | I112: 3 | J112: =MAX(I112-H112,0) | K112: https://img.alicdn.com/bao/uploaded/i4/2217590670593/O1CN01Z5hiwq1GFdv2jmgHC_!!2217590670593.jpg
A113: 110 | C113: NN-2515 | D113: 扭捏niunie 复古vintage宽松慵懒感上衣 果实扣100%苎麻衬衫夏季 | E113: 黄色 | F113: S | G113: 398 | H113: 16 | I113: 3 | J113: =MAX(I113-H113,0) | K113: https://img.alicdn.com/bao/uploaded/i4/2217590670593/O1CN01Z5hiwq1GFdv2jmgHC_!!2217590670593.jpg
A114: 111 | B114: NTF0311W-1-L | C114: NTF-0311 | D114: 扭捏 少女的祈祷 花边拼接蛋糕a字小短裙白色半身裙 防走光内衬 | E114: 白色拼接短裙 （绗缝位置改版） | F114: L | G114: 338 | H114: 13 | I114: 3 | J114: =MAX(I114-H114,0) | K114: https://img.alicdn.com/bao/uploaded/i1/2217590670593/O1CN01ZmqRQD1GFdwea86Gu_!!2217590670593.jpg
A115: 112 | B115: NTF0311W-1-M | C115: NTF-0311 | D115: 扭捏 少女的祈祷 花边拼接蛋糕a字小短裙白色半身裙 防走光内衬 | E115: 白色拼接短裙 （绗缝位置改版） | F115: M | G115: 338 | H115: 17 | I115: 3 | J115: =MAX(I115-H115,0) | K115: https://img.alicdn.com/bao/uploaded/i1/2217590670593/O1CN01ZmqRQD1GFdwea86Gu_!!2217590670593.jpg
A116: 113 | B116: NTF0311W-1-S | C116: NTF-0311 | D116: 扭捏 少女的祈祷 花边拼接蛋糕a字小短裙白色半身裙 防走光内衬 | E116: 白色拼接短裙 （绗缝位置改版） | F116: S | G116: 338 | H116: 13 | I116: 3 | J116: =MAX(I116-H116,0) | K116: https://img.alicdn.com/bao/uploaded/i1/2217590670593/O1CN01ZmqRQD1GFdwea86Gu_!!2217590670593.jpg
A117: 114 | B117: NTF0307B-L | C117: NTF0307 | D117: 扭捏niunie 玫瑰小猫可爱印花 弹力花边圆领正肩白色短袖T恤女夏 | E117: 玫瑰印花白色T恤 | F117: L | G117: 198 | H117: 0 | I117: 3 | J117: =MAX(I117-H117,0) | K117: https://img.alicdn.com/bao/uploaded/i4/2217590670593/O1CN01Luzo9Q1GFdvJKTxCd_!!2217590670593.jpg
...
